#VRML_SIM R2023b utf8

EXTERNPROTO "https://raw.githubusercontent.com/cyberbotics/webots/R2023b/projects/objects/trees/protos/BigSassafras.proto"
EXTERNPROTO "https://raw.githubusercontent.com/cyberbotics/webots/R2023b/projects/objects/trees/protos/Cypress.proto"
EXTERNPROTO "https://raw.githubusercontent.com/cyberbotics/webots/R2023b/projects/appearances/protos/DryMud.proto"
EXTERNPROTO "https://raw.githubusercontent.com/cyberbotics/webots/R2023b/projects/objects/trees/protos/Oak.proto"
EXTERNPROTO "https://raw.githubusercontent.com/cyberbotics/webots/R2023b/projects/appearances/protos/PaintedWood.proto"
EXTERNPROTO "https://raw.githubusercontent.com/cyberbotics/webots/R2023b/projects/objects/trees/protos/Pine.proto"
EXTERNPROTO "https://raw.githubusercontent.com/cyberbotics/webots/R2023b/projects/appearances/protos/Rubber.proto"
EXTERNPROTO "https://raw.githubusercontent.com/cyberbotics/webots/R2023b/projects/objects/trees/protos/SimpleTree.proto"
EXTERNPROTO "https://raw.githubusercontent.com/cyberbotics/webots/R2023b/projects/objects/backgrounds/protos/TexturedBackground.proto"
EXTERNPROTO "https://raw.githubusercontent.com/cyberbotics/webots/R2023b/projects/objects/backgrounds/protos/TexturedBackgroundLight.proto"
EXTERNPROTO "https://raw.githubusercontent.com/cyberbotics/webots/R2023b/projects/objects/floors/protos/UnevenTerrain.proto"

WorldInfo {
}
Viewpoint {
  orientation -0.2904966532796539 0.013743878742236473 0.9567772991822282 3.051130704551668
  position 35.75980449482128 -11.406578955280562 22.140179281883746
}
TexturedBackground {
}
TexturedBackgroundLight {
}
Robot {
  translation 7.20713196717972 -0.5780431774389301 4.462843673702929
  rotation 0.016609739028396225 0.03175465239599687 -0.9993576730183332 3.072214792446185
  children [
    DEF base Shape {
      appearance PaintedWood {
        colorOverride 0 0.2 0.1
      }
      geometry DEF Base Box {
        size 1.2 3 1
      }
    }
    DEF wheel1 HingeJoint {
      jointParameters HingeJointParameters {
        position -10.115473818866935
        anchor 0.75 -0.96 -0.53
      }
      device [
        RotationalMotor {
          name "wheel1"
          maxTorque 40
        }
      ]
      endPoint Solid {
        translation 0.75 -0.96 -0.53
        rotation 0.6852771334653748 0.24654087849327772 0.6852830404885574 2.6581573647882446
        children [
          DEF wheel Shape {
            appearance Rubber {
            }
            geometry Cylinder {
              height 0.5
              radius 0.5
            }
          }
        ]
        boundingObject USE wheel
        physics DEF phy1 Physics {
          mass 1
        }
        linearVelocity -3.170097176486353e-06 -9.612007201986847e-06 -6.719838051617561e-07
        angularVelocity 3.7437349507183625e-06 4.3243155706757237e-07 1.8343269524675905e-07
      }
    }
    DEF wheel2 HingeJoint {
      jointParameters HingeJointParameters {
        position -67.7684944718983
        anchor -0.75 -0.96 -0.53
      }
      device [
        RotationalMotor {
          name "wheel2"
          maxTorque 40
        }
      ]
      endPoint Solid {
        translation -0.75 -0.96 -0.53
        rotation -0.5291094462640473 -0.6633868124602575 -0.5291135331173944 4.31304063678188
        children [
          DEF wheel Shape {
            appearance Rubber {
            }
            geometry Cylinder {
              height 0.5
              radius 0.5
            }
          }
        ]
        name "solid(1)"
        boundingObject USE wheel
        physics USE phy1
        linearVelocity -2.8855689742211966e-06 -9.480031675474603e-06 -8.259867448080867e-07
        angularVelocity 3.721029803738363e-06 2.863639953956908e-07 1.7952728456833435e-07
      }
    }
    DEF wheel3 HingeJoint {
      jointParameters HingeJointParameters {
        position -20.105142160867608
        anchor 0.75 0.96 -0.53
      }
      device [
        RotationalMotor {
          name "wheel3"
          maxTorque 40
        }
      ]
      endPoint Solid {
        translation 0.75 0.96 -0.53
        rotation 0.5064552778734631 -0.6978544173072738 0.5064605253707719 4.360153955244583
        children [
          DEF wheel Shape {
            appearance Rubber {
            }
            geometry Cylinder {
              height 0.5
              radius 0.5
            }
          }
        ]
        name "solid(2)"
        boundingObject USE wheel
        physics USE phy1
        linearVelocity -3.1373746627433286e-06 -9.60172020323028e-06 -7.120215748655498e-07
        angularVelocity 3.7389806830266003e-06 4.607492999253299e-07 1.8659292842722024e-07
      }
    }
    DEF wheel4 HingeJoint {
      jointParameters HingeJointParameters {
        position -73.28029024564432
        anchor -0.75 0.96 -0.53
      }
      device [
        RotationalMotor {
          name "wheel4"
          maxTorque 40
        }
      ]
      endPoint Solid {
        translation -0.75 0.96 -0.53
        rotation 0.6571556906853823 0.36916869602597585 0.657161222284379 2.4343026099262524
        children [
          DEF wheel Shape {
            appearance Rubber {
            }
            geometry Cylinder {
              height 0.5
              radius 0.5
            }
          }
        ]
        name "solid(3)"
        boundingObject USE wheel
        physics USE phy1
        linearVelocity -2.7952061643491617e-06 -9.42849754476372e-06 -8.597031757000097e-07
        angularVelocity 3.703132140700874e-06 2.8432143156332445e-07 1.6801895302511615e-07
      }
    }
  ]
  boundingObject USE base
  physics USE phy1
  controller "my_controller"
  linearVelocity -2.936347401903294e-06 -9.537672165293997e-06 -7.660062588570327e-07
  angularVelocity 1.1751768152765696e-08 1.1133245620083577e-07 5.400187122119579e-08
}
DEF forest Solid {
  children [
    Pine {
      translation -15.62 20.85 1.15
      name "pine tree(6)"
    }
    Pine {
      translation -15.62 -10.45 1.15
      name "pine tree(5)"
    }
    Pine {
      translation 11.67 -10.45 1.45
      name "pine tree(3)"
    }
    Pine {
      translation 20.49 -10.45 2.81
      name "pine tree(4)"
    }
    Pine {
      translation 11.67 15.84 1.88
      name "pine tree(2)"
    }
    Pine {
      translation -4.35 9.25 2.22
      name "pine tree(1)"
    }
    Pine {
      translation -4.35 -3.53 2.18
    }
    SimpleTree {
      translation 0 0 3
    }
    SimpleTree {
      translation 6 0 3
      name "tree(1)"
    }
    SimpleTree {
      translation 6 10 3
      name "tree(2)"
    }
    SimpleTree {
      translation 16 15 3
      name "tree(3)"
    }
    SimpleTree {
      translation -16 -15 1.8
      name "tree(4)"
    }
    SimpleTree {
      translation 16 -15 3
      name "tree(5)"
    }
    SimpleTree {
      translation 5 -22 2
      name "tree(6)"
    }
    SimpleTree {
      translation -15 -22 2
      name "tree(7)"
    }
    SimpleTree {
      translation -9 22 2
      name "tree(8)"
    }
    SimpleTree {
      translation -18 16 2.5
      name "tree(9)"
    }
    SimpleTree {
      translation -22 -3 2
      name "tree(10)"
    }
    SimpleTree {
      translation 10 -8 3
      name "tree(11)"
    }
    SimpleTree {
      translation -5 -8 2.3
      name "tree(12)"
    }
    SimpleTree {
      translation 1 -17 2
      name "tree(13)"
    }
    Oak {
      translation 14.94 0 3.24
    }
    Oak {
      translation 20 -5.97 3.28
      name "oak tree(1)"
    }
    Oak {
      translation 15.97 -10.75 3.02
      name "oak tree(2)"
    }
    Oak {
      translation 15.97 11.04 3.07
      name "oak tree(3)"
    }
    Oak {
      translation -24.52 6.27 2.46
      name "oak tree(4)"
    }
    Oak {
      translation -12.06 2.39 2.09
      name "oak tree(6)"
    }
    Oak {
      translation -13.84 10.96 2.09
      name "oak tree(7)"
    }
    Oak {
      translation -2.97 18.97 1.79
      name "oak tree(8)"
    }
    Oak {
      translation 0.35 13.07 2.24
      name "oak tree(9)"
    }
    Oak {
      translation -9.22 15.64 2.72
      name "oak tree(5)"
    }
    Oak {
      translation 7.46 20.45 2.43
      name "oak tree(10)"
    }
    Oak {
      translation 16.74 21.4 2.43
      name "oak tree(11)"
    }
    BigSassafras {
      translation -11.82 -13.71 1.72
    }
    BigSassafras {
      translation -21.32 -8.95 1.72
      name "sassafras tree(1)"
    }
    BigSassafras {
      translation 19.67 7.95 3.44
      name "sassafras tree(2)"
    }
    BigSassafras {
      translation 19.67 -1.13 2.97
      name "sassafras tree(3)"
    }
    BigSassafras {
      translation 21.66 -19.93 2.97
      name "sassafras tree(4)"
    }
    BigSassafras {
      translation 9.84 -19.93 2.64
      name "sassafras tree(5)"
    }
    BigSassafras {
      translation -6.69 -19.93 1.29
      name "sassafras tree(6)"
    }
    BigSassafras {
      translation -16.82 -5.16 2.98
      name "sassafras tree(7)"
    }
    BigSassafras {
      translation -16.82 8.12 2.98
      name "sassafras tree(8)"
    }
    BigSassafras {
      translation -21.82 21.14 2.98
      name "sassafras tree(9)"
    }
    BigSassafras {
      translation 1.95 21.14 2.63
      name "sassafras tree(10)"
    }
    Cypress {
      translation -11.36 0 1.96
    }
    Cypress {
      translation -14.16 5.78 2.06
      name "cypress tree(1)"
    }
    Cypress {
      translation 20.42 15.8 3.01
      name "cypress tree(2)"
    }
    Cypress {
      translation 21.87 20.79 3.01
      name "cypress tree(3)"
    }
    Cypress {
      translation 11.51 1.81 3.01
      name "cypress tree(4)"
    }
    Cypress {
      translation 2.77 -10.75 2.51
      name "cypress tree(5)"
    }
    Cypress {
      translation -2.24 -21.57 1.87
      name "cypress tree(6)"
    }
    Cypress {
      translation 15.22 -21.57 2.5
      name "cypress tree(7)"
    }
    Cypress {
      translation 6.61 -15.53 2.8
      name "cypress tree(8)"
    }
    Cypress {
      translation -11.26 5.51 2.26
      name "cypress tree(9)"
    }
  ]
}
UnevenTerrain {
}
DEF Border Solid {
  translation 0 0 3.9
  children [
    Solid {
      translation 0 -25.2 -0.3700784023166439
      children [
        DEF border Shape {
          appearance DryMud {
          }
          geometry Box {
            size 49 1 3
          }
        }
      ]
      name "border1"
      boundingObject USE border
      physics DEF phy1 Physics {
        mass 1
      }
      linearVelocity 0 0 -1.2139209860606136e-07
    }
    Solid {
      translation 0 25.53 -0.3700784023166439
      children [
        DEF border Shape {
          appearance DryMud {
          }
          geometry Box {
            size 49 1 3
          }
        }
      ]
      name "border2"
      boundingObject USE border
      physics USE phy1
      linearVelocity 0 0 -1.2139209860606136e-07
    }
    Solid {
      translation 25.53 0 -0.37
      rotation 0 0 1 1.5708
      children [
        DEF border Shape {
          appearance DryMud {
          }
          geometry Box {
            size 49 1 3
          }
        }
      ]
      name "border3"
      boundingObject USE border
    }
    Solid {
      translation -25.5301 1.57462e-05 -0.3700784023166439
      rotation 5.1580022398749126e-05 -9.550089548459884e-05 0.9999999941095401 1.569814080916819
      children [
        DEF border Shape {
          appearance DryMud {
          }
          geometry Box {
            size 49 1 3
          }
        }
      ]
      name "border4"
      boundingObject USE border
      physics USE phy1
      linearVelocity 0 0 -1.2139209860606136e-07
    }
  ]
  name "solid(1)"
}
